<?xml version="1.0" ?>
<!-- =================================================================================== -->
<!-- |    This document was autogenerated by xacro from src/mimic_support/urdf/mimic.xacro | -->
<!-- |    EDITING THIS FILE BY HAND IS NOT RECOMMENDED                                 | -->
<!-- =================================================================================== -->
<robot name="mimic_slave">
  <!-- LINKS -->
  <link name="master_positioner_frame">
    <visual>
      <origin rpy="0 0 0" xyz="0 0 0"/>
      <geometry>
        <mesh filename="package://mimic_support/meshes/visual/positioner_fixed_nx.dae"/>
      </geometry>
    </visual>
    <collision>
      <origin rpy="0 0 0" xyz="0 0 0"/>
      <geometry>
        <mesh filename="package://mimic_support/meshes/collision/positioner_fixed_nx.stl"/>
      </geometry>
    </collision>
  </link>
  <link name="master_e1">
    <inertial>
      <origin rpy="0 0 0" xyz="0 0 0"/>
      <mass value="2"/>
      <inertia ixx="0.01" ixy="0" ixz="0" iyy="0.01" iyz="0" izz="0.01"/>
    </inertial>
    <visual>
      <origin rpy="0 0 0" xyz="0 0 0"/>
      <geometry>
        <mesh filename="package://mimic_support/meshes/visual/e1_nx.dae"/>
      </geometry>
    </visual>
    <collision>
      <origin rpy="0 0 0" xyz="0 0 0"/>
      <geometry>
        <mesh filename="package://mimic_support/meshes/collision/e1_nx.stl"/>
      </geometry>
    </collision>
  </link>
  <link name="master_e2">
    <inertial>
      <origin rpy="0 0 0" xyz="0 0 0"/>
      <mass value="2"/>
      <inertia ixx="0.01" ixy="0" ixz="0" iyy="0.01" iyz="0" izz="0.01"/>
    </inertial>
    <visual>
      <origin rpy="0 0 0" xyz="0 0 0"/>
      <geometry>
        <mesh filename="package://mimic_support/meshes/visual/e2_nx.dae"/>
      </geometry>
    </visual>
    <collision>
      <origin rpy="0 0 0" xyz="0 0 0"/>
      <geometry>
        <mesh filename="package://mimic_support/meshes/collision/e2_nx.stl"/>
      </geometry>
    </collision>
  </link>
  <!-- JOINTS -->
  <!-- joint e1 (E1) -->
  <joint name="master_joint_e1" type="revolute">
    <origin rpy="0 0 0" xyz="0.0 0.0 0.0"/>
    <parent link="master_positioner_frame"/>
    <child link="master_e1"/>
    <axis xyz="1 0 0"/>
    <limit effort="21.9" lower="-0.04363323129985824" upper="2.050761871093337" velocity="0.714"/>
  </joint>
  <joint name="master_joint_e2" type="revolute">
    <origin rpy="0 0 0" xyz="0 0 0"/>
    <parent link="master_e1"/>
    <child link="master_e2"/>
    <axis xyz="0 0 1"/>
    <limit effort="21.9" lower="-31.41592653589793" upper="31.41592653589793" velocity="0.2575"/>
  </joint>
  <!-- colours based on RAL values given in "FAQ - Colours of robot and robot
       controller", version "KUKA.Tifs | 2010-01-21 |YM| DefaultColorsRobotAndController.doc",
       downloaded 2015-07-18 from
       http://www.kuka.be/main/cservice/faqs/hardware/DefaultColorsRobotAndController.pdf

       all RAL colours converted using http://www.visual-graphics.de/en/customer-care/ral-colours
  -->
  <!-- LINKS -->
  <!-- base link -->
  <link name="master_base_link">
    <inertial>
      <origin rpy="0 0 0" xyz="0 0 0"/>
      <mass value="2"/>
      <inertia ixx="0.01" ixy="0" ixz="0" iyy="0.01" iyz="0" izz="0.01"/>
    </inertial>
    <visual>
      <origin rpy="0 0 0" xyz="0 0 0"/>
      <geometry>
        <mesh filename="package://kuka_kr20_support/meshes/kuka_kr20_r1810_2/visual/base_link.stl" scale="0.001 0.001 0.001"/>
      </geometry>
      <material name="">
        <color rgba="0.5058823529411764 0.47058823529411764 0.38823529411764707 1.0"/>
      </material>
    </visual>
    <collision>
      <origin rpy="0 0 0" xyz="0 0 0"/>
      <geometry>
        <mesh filename="package://kuka_kr20_support/meshes/kuka_kr20_r1810_2/collision/base_link.stl" scale="0.001 0.001 0.001"/>
      </geometry>
    </collision>
  </link>
  <!-- link 1 (A1) -->
  <link name="master_link_1">
    <inertial>
      <origin rpy="0 0 0" xyz="0 0 0"/>
      <mass value="2"/>
      <inertia ixx="0.01" ixy="0" ixz="0" iyy="0.01" iyz="0" izz="0.01"/>
    </inertial>
    <visual>
      <origin rpy="0 0 0" xyz="0 0 0"/>
      <geometry>
        <mesh filename="package://kuka_kr20_support/meshes/kuka_kr20_r1810_2/visual/link_1.stl" scale="0.001 0.001 0.001"/>
      </geometry>
      <material name="">
        <color rgba="0.9647058823529412 0.47058823529411764 0.1568627450980392 1.0"/>
      </material>
    </visual>
    <collision>
      <origin rpy="0 0 0" xyz="0 0 0"/>
      <geometry>
        <mesh filename="package://kuka_kr20_support/meshes/kuka_kr20_r1810_2/collision/link_1.stl" scale="0.001 0.001 0.001"/>
      </geometry>
    </collision>
  </link>
  <!-- link 2 -->
  <link name="master_link_2">
    <inertial>
      <origin rpy="0 0 0" xyz="0 0 0"/>
      <mass value="2"/>
      <inertia ixx="0.01" ixy="0" ixz="0" iyy="0.01" iyz="0" izz="0.01"/>
    </inertial>
    <visual>
      <origin rpy="0 0 0" xyz="0 0 0"/>
      <geometry>
        <mesh filename="package://kuka_kr20_support/meshes/kuka_kr20_r1810_2/visual/link_2.stl" scale="0.001 0.001 0.001"/>
      </geometry>
      <material name="">
        <color rgba="0.9647058823529412 0.47058823529411764 0.1568627450980392 1.0"/>
      </material>
    </visual>
    <collision>
      <origin rpy="0 0 0" xyz="0 0 0"/>
      <geometry>
        <mesh filename="package://kuka_kr20_support/meshes/kuka_kr20_r1810_2/collision/link_2.stl" scale="0.001 0.001 0.001"/>
      </geometry>
    </collision>
  </link>
  <!-- link 3 -->
  <link name="master_link_3">
    <inertial>
      <origin rpy="0 0 0" xyz="0 0 0"/>
      <mass value="2"/>
      <inertia ixx="0.01" ixy="0" ixz="0" iyy="0.01" iyz="0" izz="0.01"/>
    </inertial>
    <visual>
      <origin rpy="0 0 0" xyz="0 0 0"/>
      <geometry>
        <mesh filename="package://kuka_kr20_support/meshes/kuka_kr20_r1810_2/visual/link_3.stl" scale="0.001 0.001 0.001"/>
      </geometry>
      <material name="">
        <color rgba="0.9647058823529412 0.47058823529411764 0.1568627450980392 1.0"/>
      </material>
    </visual>
    <collision>
      <origin rpy="0 0 0" xyz="0 0 0"/>
      <geometry>
        <mesh filename="package://kuka_kr20_support/meshes/kuka_kr20_r1810_2/collision/link_3.stl" scale="0.001 0.001 0.001"/>
      </geometry>
    </collision>
  </link>
  <!-- link 4 -->
  <link name="master_link_4">
    <inertial>
      <origin rpy="0 0 0" xyz="0 0 0"/>
      <mass value="2"/>
      <inertia ixx="0.01" ixy="0" ixz="0" iyy="0.01" iyz="0" izz="0.01"/>
    </inertial>
    <visual>
      <origin rpy="0 0 0" xyz="0 0 0"/>
      <geometry>
        <mesh filename="package://kuka_kr20_support/meshes/kuka_kr20_r1810_2/visual/link_4.stl" scale="0.001 0.001 0.001"/>
      </geometry>
      <material name="">
        <color rgba="0.9647058823529412 0.47058823529411764 0.1568627450980392 1.0"/>
      </material>
    </visual>
    <collision>
      <origin rpy="0 0 0" xyz="0 0 0"/>
      <geometry>
        <mesh filename="package://kuka_kr20_support/meshes/kuka_kr20_r1810_2/collision/link_4.stl" scale="0.001 0.001 0.001"/>
      </geometry>
    </collision>
  </link>
  <!-- link 5 -->
  <link name="master_link_5">
    <inertial>
      <origin rpy="0 0 0" xyz="0 0 0"/>
      <mass value="2"/>
      <inertia ixx="0.01" ixy="0" ixz="0" iyy="0.01" iyz="0" izz="0.01"/>
    </inertial>
    <visual>
      <origin rpy="0 0 0" xyz="0 0 0"/>
      <geometry>
        <mesh filename="package://kuka_kr20_support/meshes/kuka_kr20_r1810_2/visual/link_5.stl" scale="0.001 0.001 0.001"/>
      </geometry>
      <material name="">
        <color rgba="0.9647058823529412 0.47058823529411764 0.1568627450980392 1.0"/>
      </material>
    </visual>
    <collision>
      <origin rpy="0 0 0" xyz="0 0 0"/>
      <geometry>
        <mesh filename="package://kuka_kr20_support/meshes/kuka_kr20_r1810_2/collision/link_5.stl" scale="0.001 0.001 0.001"/>
      </geometry>
    </collision>
  </link>
  <!-- link 6 -->
  <link name="master_link_6">
    <inertial>
      <origin rpy="0 0 0" xyz="0 0 0"/>
      <mass value="2"/>
      <inertia ixx="0.01" ixy="0" ixz="0" iyy="0.01" iyz="0" izz="0.01"/>
    </inertial>
    <visual>
      <origin rpy="0 0 0" xyz="0 0 0"/>
      <geometry>
        <mesh filename="package://kuka_kr20_support/meshes/kuka_kr20_r1810_2/visual/link_6.stl" scale="0.001 0.001 0.001"/>
      </geometry>
      <material name="">
        <color rgba="0.5058823529411764 0.47058823529411764 0.38823529411764707 1.0"/>
      </material>
    </visual>
    <collision>
      <origin rpy="0 0 0" xyz="0 0 0"/>
      <geometry>
        <mesh filename="package://kuka_kr20_support/meshes/kuka_kr20_r1810_2/collision/link_6.stl" scale="0.001 0.001 0.001"/>
      </geometry>
    </collision>
  </link>
  <!-- tool 0 -->
  <!-- This frame corresponds to the $FLANGE coordinate system in KUKA KRC controllers. -->
  <link name="master_tool0"/>
  <!-- END LINKS -->
  <!-- JOINTS -->
  <!-- joint 1 (A1) -->
  <joint name="master_joint_a1" type="revolute">
    <origin rpy="0 0 0" xyz="0 0 0.520"/>
    <parent link="master_base_link"/>
    <child link="master_link_1"/>
    <axis xyz="0 0 -1"/>
    <limit effort="2500" lower="-3.2288591161895095" upper="3.2288591161895095" velocity="3.490658503988659"/>
  </joint>
  <!-- joint 2 (A2) -->
  <joint name="master_joint_a2" type="revolute">
    <origin rpy="0 0 0" xyz="0.160 0 0"/>
    <parent link="master_link_1"/>
    <child link="master_link_2"/>
    <axis xyz="0 1 0"/>
    <limit effort="3100" lower="-3.2288591161895095" upper="1.1344640137963142" velocity="3.0543261909900767"/>
  </joint>
  <!-- joint 3 (A3) -->
  <joint name="master_joint_a3" type="revolute">
    <origin rpy="0 0 0" xyz="0.780 0 0.0"/>
    <parent link="master_link_2"/>
    <child link="master_link_3"/>
    <axis xyz="0 1 0"/>
    <limit effort="2200" lower="-2.4085543677521746" upper="3.0543261909900767" velocity="3.3161255787892263"/>
  </joint>
  <!-- joint 4 (A4) -->
  <joint name="master_joint_a4" type="revolute">
    <origin rpy="0 0 0" xyz="0.0 0 0.150"/>
    <parent link="master_link_3"/>
    <child link="master_link_4"/>
    <axis xyz="-1 0 0"/>
    <limit effort="500" lower="-6.1086523819801535" upper="6.1086523819801535" velocity="7.504915783575617"/>
  </joint>
  <!-- joint 5 (A5) -->
  <joint name="master_joint_a5" type="revolute">
    <origin rpy="0 0 0" xyz="0.860 0 0"/>
    <parent link="master_link_4"/>
    <child link="master_link_5"/>
    <axis xyz="0 1 0"/>
    <limit effort="500" lower="-2.2689280275926285" upper="2.2689280275926285" velocity="7.504915783575617"/>
  </joint>
  <!-- joint 6 (A6) -->
  <joint name="master_joint_a6" type="revolute">
    <origin rpy="0 0 0" xyz="0.153 0 0"/>
    <parent link="master_link_5"/>
    <child link="master_link_6"/>
    <axis xyz="-1 0 0"/>
    <limit effort="150" lower="-6.1086523819801535" upper="6.1086523819801535" velocity="10.995574287564276"/>
  </joint>
  <!-- tool frame - fixed frame -->
  <joint name="master_joint_a6-tool0" type="fixed">
    <parent link="master_link_6"/>
    <child link="master_tool0"/>
    <origin rpy="0 1.5707963267948966 0" xyz="0.0 0 0"/>
  </joint>
  <!-- END JOINTS -->
  <!-- ROS base_link to KUKA $ROBROOT coordinate system transform -->
  <link name="master_base"/>
  <joint name="master_base_link-base" type="fixed">
    <origin rpy="0 0 0" xyz="0 0 0"/>
    <parent link="master_base_link"/>
    <child link="master_base"/>
  </joint>
  <!-- LINKS -->
  <link name="slave_gantry_frame">
    <visual>
      <origin rpy="0 0 0" xyz="0 0 0"/>
      <geometry>
        <mesh filename="package://mimic_support/meshes/visual/gantry_fixed.dae"/>
      </geometry>
    </visual>
    <collision>
      <origin rpy="0 0 0" xyz="0 0 0"/>
      <geometry>
        <mesh filename="package://mimic_support/meshes/collision/gantry_fixed.stl"/>
      </geometry>
    </collision>
  </link>
  <link name="slave_gantry_x">
    <inertial>
      <origin rpy="0 0 0" xyz="0 0 0"/>
      <mass value="2"/>
      <inertia ixx="0.01" ixy="0" ixz="0" iyy="0.01" iyz="0" izz="0.01"/>
    </inertial>
    <visual>
      <origin rpy="0 0 0" xyz="0 0 0"/>
      <geometry>
        <mesh filename="package://mimic_support/meshes/visual/gantry_x.dae"/>
      </geometry>
    </visual>
    <collision>
      <origin rpy="0 0 0" xyz="0 0 0"/>
      <geometry>
        <mesh filename="package://mimic_support/meshes/collision/gantry_x.stl"/>
      </geometry>
    </collision>
  </link>
  <link name="slave_gantry_y">
    <inertial>
      <origin rpy="0 0 0" xyz="0 0 0"/>
      <mass value="2"/>
      <inertia ixx="0.01" ixy="0" ixz="0" iyy="0.01" iyz="0" izz="0.01"/>
    </inertial>
    <visual>
      <origin rpy="0 0 0" xyz="0 0 0"/>
      <geometry>
        <mesh filename="package://mimic_support/meshes/visual/gantry_y.dae"/>
      </geometry>
    </visual>
    <collision>
      <origin rpy="0 0 0" xyz="0 0 0"/>
      <geometry>
        <mesh filename="package://mimic_support/meshes/collision/gantry_y.stl"/>
      </geometry>
    </collision>
  </link>
  <link name="slave_gantry_z">
    <inertial>
      <origin rpy="0 0 0" xyz="0 0 0"/>
      <mass value="2"/>
      <inertia ixx="0.01" ixy="0" ixz="0" iyy="0.01" iyz="0" izz="0.01"/>
    </inertial>
    <visual>
      <origin rpy="0 0 0" xyz="0 0 0"/>
      <geometry>
        <mesh filename="package://mimic_support/meshes/visual/gantry_z.dae"/>
      </geometry>
    </visual>
    <collision>
      <origin rpy="0 0 0" xyz="0 0 0"/>
      <geometry>
        <mesh filename="package://mimic_support/meshes/collision/gantry_z.stl"/>
      </geometry>
    </collision>
  </link>
  <!-- JOINTS -->
  <!-- joint e1 (E1) -->
  <joint name="slave_joint_e1" type="prismatic">
    <origin rpy="0 0 0" xyz="0.011 0 0"/>
    <parent link="slave_gantry_frame"/>
    <child link="slave_gantry_x"/>
    <axis xyz="1 0 0"/>
    <limit effort="12" lower="-0.011" upper="3.0" velocity="0.1"/>
  </joint>
  <joint name="slave_joint_e2" type="prismatic">
    <origin rpy="0 0 0" xyz="0 0.015 0"/>
    <parent link="slave_gantry_x"/>
    <child link="slave_gantry_y"/>
    <axis xyz="0 1 0"/>
    <limit effort="25" lower="-0.015" upper="2.25" velocity="0.4"/>
  </joint>
  <joint name="slave_joint_e3" type="prismatic">
    <origin rpy="0 0 0" xyz="0 0 0.011"/>
    <parent link="slave_gantry_y"/>
    <child link="slave_gantry_z"/>
    <axis xyz="0 0 -1"/>
    <limit effort="79" lower="-0.011" upper="2.6" velocity="0.1"/>
  </joint>
  <!-- LINKS -->
  <!-- base link -->
  <link name="slave_base_link">
    <inertial>
      <origin rpy="0 0 0" xyz="0 0 0"/>
      <mass value="2500"/>
      <inertia ixx="0.01" ixy="0" ixz="0" iyy="0.01" iyz="0" izz="0.01"/>
    </inertial>
    <visual>
      <origin rpy="0 0 0" xyz="0 0 0"/>
      <geometry>
        <mesh filename="package://kuka_kr16_support/meshes/kr16_2/visual/base_link.dae"/>
      </geometry>
    </visual>
    <collision>
      <origin rpy="0 0 0" xyz="0 0 0"/>
      <geometry>
        <mesh filename="package://kuka_kr16_support/meshes/kr16_2/collision/base_link.stl"/>
      </geometry>
    </collision>
  </link>
  <!-- link 1 (A1) -->
  <link name="slave_link_1">
    <inertial>
      <origin rpy="0 0 0" xyz="0 0 0"/>
      <mass value="2"/>
      <inertia ixx="0.01" ixy="0" ixz="0" iyy="0.01" iyz="0" izz="0.01"/>
    </inertial>
    <visual>
      <origin rpy="0 0 0" xyz="0 0 0"/>
      <geometry>
        <mesh filename="package://kuka_kr16_support/meshes/kr16_2/visual/link_1.dae"/>
      </geometry>
    </visual>
    <collision>
      <origin rpy="0 0 0" xyz="0 0 0"/>
      <geometry>
        <mesh filename="package://kuka_kr16_support/meshes/kr16_2/collision/link_1.stl"/>
      </geometry>
    </collision>
  </link>
  <!-- link 2 -->
  <link name="slave_link_2">
    <inertial>
      <origin rpy="0 0 0" xyz="0 0 0"/>
      <mass value="2"/>
      <inertia ixx="0.01" ixy="0" ixz="0" iyy="0.01" iyz="0" izz="0.01"/>
    </inertial>
    <visual>
      <origin rpy="0 0 0" xyz="0 0 0"/>
      <geometry>
        <mesh filename="package://kuka_kr16_support/meshes/kr16_2/visual/link_2.dae"/>
      </geometry>
    </visual>
    <collision>
      <origin rpy="0 0 0" xyz="0 0 0"/>
      <geometry>
        <mesh filename="package://kuka_kr16_support/meshes/kr16_2/collision/link_2.stl"/>
      </geometry>
    </collision>
  </link>
  <!-- link 3 -->
  <link name="slave_link_3">
    <inertial>
      <origin rpy="0 0 0" xyz="0 0 0"/>
      <mass value="2"/>
      <inertia ixx="0.01" ixy="0" ixz="0" iyy="0.01" iyz="0" izz="0.01"/>
    </inertial>
    <visual>
      <origin rpy="0 0 0" xyz="0 0 0"/>
      <geometry>
        <mesh filename="package://kuka_kr16_support/meshes/kr16_2/visual/link_3.dae"/>
      </geometry>
    </visual>
    <collision>
      <origin rpy="0 0 0" xyz="0 0 0"/>
      <geometry>
        <mesh filename="package://kuka_kr16_support/meshes/kr16_2/collision/link_3.stl"/>
      </geometry>
    </collision>
  </link>
  <!-- link 4 -->
  <link name="slave_link_4">
    <inertial>
      <origin rpy="0 0 0" xyz="0 0 0"/>
      <mass value="2"/>
      <inertia ixx="0.01" ixy="0" ixz="0" iyy="0.01" iyz="0" izz="0.01"/>
    </inertial>
    <visual>
      <origin rpy="0 0 0" xyz="0 0 0"/>
      <geometry>
        <mesh filename="package://kuka_kr16_support/meshes/kr16_2/visual/link_4.dae"/>
      </geometry>
    </visual>
    <collision>
      <origin rpy="0 0 0" xyz="0 0 0"/>
      <geometry>
        <mesh filename="package://kuka_kr16_support/meshes/kr16_2/collision/link_4.stl"/>
      </geometry>
    </collision>
  </link>
  <!-- link 5 -->
  <link name="slave_link_5">
    <inertial>
      <origin rpy="0 0 0" xyz="0 0 0"/>
      <mass value="2"/>
      <inertia ixx="0.01" ixy="0" ixz="0" iyy="0.01" iyz="0" izz="0.01"/>
    </inertial>
    <visual>
      <origin rpy="0 0 0" xyz="0 0 0"/>
      <geometry>
        <mesh filename="package://kuka_kr16_support/meshes/kr16_2/visual/link_5.dae"/>
      </geometry>
    </visual>
    <collision>
      <origin rpy="0 0 0" xyz="0 0 0"/>
      <geometry>
        <mesh filename="package://kuka_kr16_support/meshes/kr16_2/collision/link_5.stl"/>
      </geometry>
    </collision>
  </link>
  <!-- link 6 -->
  <link name="slave_link_6">
    <inertial>
      <origin rpy="0 0 0" xyz="0 0 0"/>
      <mass value="2"/>
      <inertia ixx="0.01" ixy="0" ixz="0" iyy="0.01" iyz="0" izz="0.01"/>
    </inertial>
    <visual>
      <origin rpy="0 0 0" xyz="0 0 0"/>
      <geometry>
        <mesh filename="package://kuka_kr16_support/meshes/kr16_2/visual/link_6.dae"/>
      </geometry>
    </visual>
    <collision>
      <origin rpy="0 0 0" xyz="0 0 0"/>
      <geometry>
        <mesh filename="package://kuka_kr16_support/meshes/kr16_2/collision/link_6.stl"/>
      </geometry>
    </collision>
  </link>
  <!-- tool 0 -->
  <!-- Following REP199, this frame shall be use to attach EEF or other equipment -->
  <link name="slave_flange"/>
  <!-- END LINKS -->
  <!-- JOINTS -->
  <!-- joint 1 (A1) -->
  <joint name="slave_joint_a1" type="revolute">
    <origin rpy="0 0 0" xyz="0 0 0.675"/>
    <parent link="slave_base_link"/>
    <child link="slave_link_1"/>
    <axis xyz="0 0 -1"/>
    <limit effort="2500" lower="-3.2288591161895095" upper="3.2288591161895095" velocity="2.722713633111154"/>
  </joint>
  <!-- joint 2 (A2) -->
  <joint name="slave_joint_a2" type="revolute">
    <origin rpy="0 0 0" xyz="0.26 0 0"/>
    <parent link="slave_link_1"/>
    <child link="slave_link_2"/>
    <axis xyz="0 1 0"/>
    <limit effort="3100" lower="-2.705260340591211" upper="0.6108652381980153" velocity="2.722713633111154"/>
  </joint>
  <!-- joint 3 (A3) -->
  <joint name="slave_joint_a3" type="revolute">
    <origin rpy="0 0 0" xyz="0.68 0 0"/>
    <parent link="slave_link_2"/>
    <child link="slave_link_3"/>
    <axis xyz="0 1 0"/>
    <limit effort="2200" lower="-2.2689280275926285" upper="2.6878070480712677" velocity="2.722713633111154"/>
  </joint>
  <!-- joint 4 (A4) -->
  <joint name="slave_joint_a4" type="revolute">
    <origin rpy="0 0 0" xyz="0.67 0 -0.035"/>
    <parent link="slave_link_3"/>
    <child link="slave_link_4"/>
    <axis xyz="-1 0 0"/>
    <limit effort="500" lower="-6.1086523819801535" upper="6.1086523819801535" velocity="5.759586531581287"/>
  </joint>
  <!-- joint 5 (A5) -->
  <joint name="slave_joint_a5" type="revolute">
    <origin rpy="0 0 0" xyz="0 0 0"/>
    <parent link="slave_link_4"/>
    <child link="slave_link_5"/>
    <axis xyz="0 1 0"/>
    <limit effort="500" lower="-2.2689280275926285" upper="2.2689280275926285" velocity="5.759586531581287"/>
  </joint>
  <!-- joint 6 (A6) -->
  <joint name="slave_joint_a6" type="revolute">
    <origin rpy="0 0 0" xyz="0 0 0"/>
    <parent link="slave_link_5"/>
    <child link="slave_link_6"/>
    <axis xyz="-1 0 0"/>
    <limit effort="150" lower="-6.1086523819801535" upper="6.1086523819801535" velocity="10.733774899765127"/>
  </joint>
  <!-- tool frame - fixed frame -->
  <joint name="slave_joint_a6-flange" type="fixed">
    <parent link="slave_link_6"/>
    <child link="slave_flange"/>
    <origin rpy="0 0 0" xyz="0.158 0 0"/>
  </joint>
  <!-- END JOINTS -->
  <!-- ROS base_link to KUKA $ROBROOT coordinate system transform -->
  <link name="slave_base"/>
  <joint name="slave_base_link-base" type="fixed">
    <origin rpy="0 0 0" xyz="0 0 0"/>
    <parent link="slave_base_link"/>
    <child link="slave_base"/>
  </joint>
  <!-- This frame corresponds to the $TOOL coordinate system in KUKA KRC controllers -->
  <link name="slave_tool0"/>
  <joint name="slave_flange-tool0" type="fixed">
    <parent link="slave_flange"/>
    <child link="slave_tool0"/>
    <origin rpy="0 1.5707963267948966 0" xyz="0 0 0"/>
  </joint>
  <link name="world"/>
  <link name="master_positioner_side"/>
  <link name="slave_ktig_eef">
    <inertial>
      <origin rpy="0 0 0" xyz="0 0 0"/>
      <mass value="2"/>
      <inertia ixx="0.01" ixy="0" ixz="0" iyy="0.01" iyz="0" izz="0.01"/>
    </inertial>
    <visual>
      <origin rpy="0 0 0" xyz="0 0 0"/>
      <geometry>
        <mesh filename="package://mimic_support/meshes/visual/ktig_eef_v2.dae" scale="0.001 0.001 0.001"/>
      </geometry>
    </visual>
    <collision>
      <origin rpy="0 0 0" xyz="0 0 0"/>
      <geometry>
        <mesh filename="package://mimic_support/meshes/collision/ktig_eef_v2.stl" scale="0.001 0.001 0.001"/>
      </geometry>
    </collision>
  </link>
  <joint name="world-master_positioner_side_joint" type="fixed">
    <parent link="world"/>
    <child link="master_positioner_side"/>
    <origin rpy="0 0 0" xyz="0 0 0"/>
  </joint>
  <joint name="master_positioner_side-master_base_link" type="fixed">
    <parent link="master_positioner_side"/>
    <child link="master_base_link"/>
    <origin rpy="9.5e-05 -0.00184 -0.90717" xyz="-0.7260644 -0.509355 -0.603812"/>
  </joint>
  <joint name="master_positioner_side-slave_gantry_frame" type="fixed">
    <parent link="master_positioner_side"/>
    <child link="slave_gantry_frame"/>
    <!-- <origin xyz="-1.1385215 -1.267 3.768157" rpy="0.00804 -0.00685 -0.00807" /> -->
    <origin rpy="0.00804 -0.00685 -0.0080815" xyz="-1.6454453024932296 -1.252142034197534 3.779355489407589"/>
  </joint>
  <joint name="master_positioner_side-master_positioner_frame" type="fixed">
    <parent link="master_positioner_side"/>
    <child link="master_positioner_frame"/>
    <origin rpy="0.0 0.0 0.0" xyz="0.48839 0.390 -0.195"/>
  </joint>
  <joint name="slave_gantry_frame-slave_base_link" type="fixed">
    <parent link="slave_gantry_z"/>
    <child link="slave_base_link"/>
    <origin rpy="3.141592653589793 0 0" xyz="0 0 0"/>
  </joint>
  <joint name="slave_tool0-slave_ktig_eef" type="fixed">
    <parent link="slave_tool0"/>
    <child link="slave_ktig_eef"/>
    <!-- we should get these values from tool on Kuka pendant -->
    <!-- <origin xyz="0.0811 0.04116 0.4408" rpy="${radians(-179.61)} ${radians(-41.39)} ${radians(-153.95)}" /> -->
    <origin rpy="-3.1553807546805483 -0.8457865555164521 -2.683618257866481" xyz="0.09142 0.04817 0.43987"/>
  </joint>
  <!-- <link name="test_positioner_side" /> -->
  <!-- <link name="test_slave_tool0" />
        <link name="test_slave_base_link" />
        <link name="test_slave_gantry_frame" />

        <joint name="world-test_positioner_side" type="fixed">
            <parent link="world" />
            <child link="test_positioner_side" />
            <origin xyz="0 0 0" rpy="0 0 0"  />
        </joint>
        <joint name="test_positioner_side-test_tool0" type="fixed">
            <parent link="test_positioner_side" />
            <child link="test_slave_tool0" />
            <origin xyz="-0.258976 0.4061174 0.6052054" rpy="${radians(-154.819)} ${radians(38.9068)} ${radians(-146.213)}"  />
        </joint>
        <joint name="test_slave_tool0-test_slave_base_link" type="fixed">
            <parent link="test_slave_tool0" />
            <child link="test_slave_base_link" />
            <origin xyz="-1.03932 0.11033 -1.253455" rpy="0.052877306944842856 -0.7816220773823008 -2.7196170270177986"  />
        </joint>
        <joint name="test_slave_base_link-test_slave_gantry_frame" type="fixed">
            <parent link="test_slave_base_link" />
            <child link="test_slave_gantry_frame" />
            <origin xyz="-1.10918 2.24999 -1.70100" rpy="0.0 0.0 0.0"  />
        </joint> -->
  <!-- 
        positioner side to slave base link
        -0.5065105324997785, 1.0023177751521826, 2.1041316744423137

        positioner side to gantry_frame
        -0.50651 - 1.10918 + 0.011 = -1.60469
        1.002317 - 2.24999 + 0.015 = -1.232673
        2.104132 + 1.70100 + 0.011 = 3.816132 -->
</robot>

