<?xml version="1.0" ?>
<!-- =================================================================================== -->
<!-- |    This document was autogenerated by xacro from src/mimic_support/urdf/positioner.xacro | -->
<!-- |    EDITING THIS FILE BY HAND IS NOT RECOMMENDED                                 | -->
<!-- =================================================================================== -->
<!--Generates a urdf from the macro in positioner_macro.xacro -->
<robot name="gantry">
  <!-- LINKS -->
  <link name="positioner_frame">
    <visual>
      <origin rpy="0 0 0" xyz="0 0 0"/>
      <geometry>
        <mesh filename="package://mimic_support/meshes/visual/positioner_fixed_nx.dae"/>
      </geometry>
    </visual>
    <collision>
      <origin rpy="0 0 0" xyz="0 0 0"/>
      <geometry>
        <mesh filename="package://mimic_support/meshes/collision/positioner_fixed_nx.stl"/>
      </geometry>
    </collision>
  </link>
  <link name="e1">
    <inertial>
      <origin rpy="0 0 0" xyz="0 0 0"/>
      <mass value="2"/>
      <inertia ixx="0.01" ixy="0" ixz="0" iyy="0.01" iyz="0" izz="0.01"/>
    </inertial>
    <visual>
      <origin rpy="0 0 0" xyz="0 0 0"/>
      <geometry>
        <mesh filename="package://mimic_support/meshes/visual/e1_nx.dae"/>
      </geometry>
    </visual>
    <collision>
      <origin rpy="0 0 0" xyz="0 0 0"/>
      <geometry>
        <mesh filename="package://mimic_support/meshes/collision/e1_nx.stl"/>
      </geometry>
    </collision>
  </link>
  <link name="e2">
    <inertial>
      <origin rpy="0 0 0" xyz="0 0 0"/>
      <mass value="2"/>
      <inertia ixx="0.01" ixy="0" ixz="0" iyy="0.01" iyz="0" izz="0.01"/>
    </inertial>
    <visual>
      <origin rpy="0 0 0" xyz="0 0 0"/>
      <geometry>
        <mesh filename="package://mimic_support/meshes/visual/e2_nx.dae"/>
      </geometry>
    </visual>
    <collision>
      <origin rpy="0 0 0" xyz="0 0 0"/>
      <geometry>
        <mesh filename="package://mimic_support/meshes/collision/e2_nx.stl"/>
      </geometry>
    </collision>
  </link>
  <!-- JOINTS -->
  <!-- joint e1 (E1) -->
  <joint name="joint_e1" type="revolute">
    <origin rpy="0 0 0" xyz="0.0 0.0 0.0"/>
    <parent link="positioner_frame"/>
    <child link="e1"/>
    <axis xyz="1 0 0"/>
    <limit effort="21.9" lower="-0.04363323129985824" upper="2.050761871093337" velocity="0.714"/>
  </joint>
  <joint name="joint_e2" type="revolute">
    <origin rpy="0 0 0" xyz="0 0 0"/>
    <parent link="e1"/>
    <child link="e2"/>
    <axis xyz="0 0 1"/>
    <limit effort="21.9" lower="-31.41592653589793" upper="31.41592653589793" velocity="0.2575"/>
  </joint>
</robot>

