<?xml version="1.0" ?>
<!-- =================================================================================== -->
<!-- |    This document was autogenerated by xacro from /home/faris/mimic_ws/src/mimic_support/urdf/gantry.xacro | -->
<!-- |    EDITING THIS FILE BY HAND IS NOT RECOMMENDED                                 | -->
<!-- =================================================================================== -->
<!--Generates a urdf from the macro in gantry_macro.xacro -->
<robot name="gantry">
    <!-- LINKS -->
    <link name="gantry_frame">
        <visual>
            <origin rpy="0 0 0" xyz="0 0 0" />
            <geometry>
                <mesh filename="package://mimic_support/meshes/visual/gantry_fixed.dae" />
            </geometry>
        </visual>
        <collision>
            <origin rpy="0 0 0" xyz="0 0 0" />
            <geometry>
                <mesh filename="package://mimic_support/meshes/collision/gantry_fixed.stl" />
            </geometry>
        </collision>
        <inertial>
            <mass value="0.1" />
            <origin xyz="0 0 0" rpy="0 0 0" />
            <inertia ixx="0.03" iyy="0.03" izz="0.03" ixy="0.0" ixz="0.0" iyz="0.0" />
        </inertial>
    </link>
    <link name="gantry_x">
        <inertial>
            <origin rpy="0 0 0" xyz="0 0 0" />
            <mass value="2" />
            <inertia ixx="0.01" ixy="0" ixz="0" iyy="0.01" iyz="0" izz="0.01" />
        </inertial>
        <visual>
            <origin rpy="0 0 0" xyz="0 0 0" />
            <geometry>
                <mesh filename="package://mimic_support/meshes/visual/gantry_x.dae" />
            </geometry>
        </visual>
        <collision>
            <origin rpy="0 0 0" xyz="0 0 0" />
            <geometry>
                <mesh filename="package://mimic_support/meshes/collision/gantry_x.stl" />
            </geometry>
        </collision>
    </link>
    <link name="gantry_y">
        <inertial>
            <origin rpy="0 0 0" xyz="0 0 0" />
            <mass value="2" />
            <inertia ixx="0.01" ixy="0" ixz="0" iyy="0.01" iyz="0" izz="0.01" />
        </inertial>
        <visual>
            <origin rpy="0 0 0" xyz="0 0 0" />
            <geometry>
                <mesh filename="package://mimic_support/meshes/visual/gantry_y.dae" />
            </geometry>
        </visual>
        <collision>
            <origin rpy="0 0 0" xyz="0 0 0" />
            <geometry>
                <mesh filename="package://mimic_support/meshes/collision/gantry_y.stl" />
            </geometry>
        </collision>
    </link>
    <link name="gantry_z">
        <inertial>
            <origin rpy="0 0 0" xyz="0 0 0" />
            <mass value="2" />
            <inertia ixx="0.01" ixy="0" ixz="0" iyy="0.01" iyz="0" izz="0.01" />
        </inertial>
        <visual>
            <origin rpy="0 0 0" xyz="0 0 0" />
            <geometry>
                <mesh filename="package://mimic_support/meshes/visual/gantry_z.dae" />
            </geometry>
        </visual>
        <collision>
            <origin rpy="0 0 0" xyz="0 0 0" />
            <geometry>
                <mesh filename="package://mimic_support/meshes/collision/gantry_z.stl" />
            </geometry>
        </collision>
    </link>
    <!-- JOINTS -->
    <!-- joint e1 (E1) -->
    <joint name="joint_e1" type="prismatic">
        <origin rpy="0 0 0" xyz="0.011 0 0" />
        <parent link="gantry_frame" />
        <child link="gantry_x" />
        <axis xyz="1 0 0" />
        <limit effort="12" lower="-0.011" upper="3.0" velocity="0.1" />
    </joint>
    <joint name="joint_e2" type="prismatic">
        <origin rpy="0 0 0" xyz="0 0.015 0" />
        <parent link="gantry_x" />
        <child link="gantry_y" />
        <axis xyz="0 1 0" />
        <limit effort="25" lower="-0.015" upper="2.25" velocity="0.4" />
    </joint>
    <joint name="joint_e3" type="prismatic">
        <origin rpy="0 0 0" xyz="0 0 0.011" />
        <parent link="gantry_y" />
        <child link="gantry_z" />
        <axis xyz="0 0 -1" />
        <limit effort="79" lower="-0.011" upper="2.6" velocity="0.1" />
    </joint>
    <transmission name="trans_joint_e1">
        <type>transmission_interface/SimpleTransmission</type>
        <joint name="joint_e1">
            <hardwareInterface>hardware_interface/PositionJointInterface</hardwareInterface>
        </joint>
        <actuator name="joint_e1_motor">
            <hardwareInterface>hardware_interface/PositionJointInterface</hardwareInterface>
            <mechanicalReduction>1</mechanicalReduction>
        </actuator>
    </transmission>
    <transmission name="trans_joint_e2">
        <type>transmission_interface/SimpleTransmission</type>
        <joint name="joint_e2">
            <hardwareInterface>hardware_interface/PositionJointInterface</hardwareInterface>
        </joint>
        <actuator name="joint_e2_motor">
            <hardwareInterface>hardware_interface/PositionJointInterface</hardwareInterface>
            <mechanicalReduction>1</mechanicalReduction>
        </actuator>
    </transmission>
    <transmission name="trans_joint_e3">
        <type>transmission_interface/SimpleTransmission</type>
        <joint name="joint_e3">
            <hardwareInterface>hardware_interface/PositionJointInterface</hardwareInterface>
        </joint>
        <actuator name="joint_e3_motor">
            <hardwareInterface>hardware_interface/PositionJointInterface</hardwareInterface>
            <mechanicalReduction>1</mechanicalReduction>
        </actuator>
    </transmission>
    <gazebo>
        <plugin name="gazebo_ros_control">
            <robotNamespace>/</robotNamespace>
        </plugin>
    </gazebo>
</robot>

